# Auto Fix Report

## Error File
`error_20250429_225437.txt`

## Analysis Result
```diff
Based on the error log, the issue is a `ZeroDivisionError` occurring in the `test3` function in `/app/app.py` where there's an attempt to divide by zero. Here's the solution:

1. Code patch in diff format:
```diff
--- a/app.py
+++ b/app.py
@@ -49,5 +49,8 @@
 
 
 def test3():
-    return 1/0
+    try:
+        return 1/0
+    except ZeroDivisionError:
+        return "Error: Division by zero is not allowed", 400
```

2. Fix reason:
- The original code had a hardcoded division by zero operation which will always raise an exception
- The fix adds error handling to catch the ZeroDivisionError and return a proper error message with a 400 Bad Request status code
- This is better than letting the application crash, as it:
  - Provides a meaningful error message to the client
  - Maintains proper HTTP status codes
  - Prevents the application from terminating unexpectedly

3. Testing suggestions:
- Unit test the error case:
```python
def test_test3_division_by_zero():
    with app.test_client() as client:
        response = client.get('/test3')  # or whatever endpoint calls test3
        assert response.status_code == 400
        assert b"Division by zero is not allowed" in response.data
```

- If this is part of a calculation function, also test:
  - Valid input cases (when denominator is not zero)
  - Different types of input (numbers, strings that can be converted to numbers)
  - Edge cases (very small numbers, negative numbers)

- Integration test:
  - Verify the error handling doesn't break other parts of the application
  - Check the error is properly logged if you have logging setup

- Consider adding input validation to prevent zero denominators before performing the division if this is user-provided data.

The fix assumes this is an API endpoint. If it's used internally, you might want to handle it differently (raise a more specific exception or return None). Let me know if you need a different approach.
```